Traceback (most recent call last):
  File "/opt/hostedtoolcache/Python/3.11.3/x64/lib/python3.11/site-packages/jupyter_cache/executors/utils.py", line 58, in single_nb_execution
    executenb(
  File "/opt/hostedtoolcache/Python/3.11.3/x64/lib/python3.11/site-packages/nbclient/client.py", line 1305, in execute
    return NotebookClient(nb=nb, resources=resources, km=km, **kwargs).execute()
           ^^^^^^^^^^^^^^^^^^^^^^^^^^^^^^^^^^^^^^^^^^^^^^^^^^^^^^^^^^^^^^^^^^^^^
  File "/opt/hostedtoolcache/Python/3.11.3/x64/lib/python3.11/site-packages/jupyter_core/utils/__init__.py", line 166, in wrapped
    return loop.run_until_complete(inner)
           ^^^^^^^^^^^^^^^^^^^^^^^^^^^^^^
  File "/opt/hostedtoolcache/Python/3.11.3/x64/lib/python3.11/asyncio/base_events.py", line 653, in run_until_complete
    return future.result()
           ^^^^^^^^^^^^^^^
  File "/opt/hostedtoolcache/Python/3.11.3/x64/lib/python3.11/site-packages/nbclient/client.py", line 705, in async_execute
    await self.async_execute_cell(
  File "/opt/hostedtoolcache/Python/3.11.3/x64/lib/python3.11/site-packages/nbclient/client.py", line 1058, in async_execute_cell
    await self._check_raise_for_error(cell, cell_index, exec_reply)
  File "/opt/hostedtoolcache/Python/3.11.3/x64/lib/python3.11/site-packages/nbclient/client.py", line 914, in _check_raise_for_error
    raise CellExecutionError.from_cell_and_msg(cell, exec_reply_content)
nbclient.exceptions.CellExecutionError: An error occurred while executing the following cell:
------------------
WImage(filename=os.path.join(os.getcwd(), 'mtrs_media', 'uf_diags_real.pdf[0]'))
------------------


[0;31m---------------------------------------------------------------------------[0m
[0;31mPolicyError[0m                               Traceback (most recent call last)
Cell [0;32mIn[13], line 1[0m
[0;32m----> 1[0m [43mWImage[49m[43m([49m[43mfilename[49m[38;5;241;43m=[39;49m[43mos[49m[38;5;241;43m.[39;49m[43mpath[49m[38;5;241;43m.[39;49m[43mjoin[49m[43m([49m[43mos[49m[38;5;241;43m.[39;49m[43mgetcwd[49m[43m([49m[43m)[49m[43m,[49m[43m [49m[38;5;124;43m'[39;49m[38;5;124;43mmtrs_media[39;49m[38;5;124;43m'[39;49m[43m,[49m[43m [49m[38;5;124;43m'[39;49m[38;5;124;43muf_diags_real.pdf[0][39;49m[38;5;124;43m'[39;49m[43m)[49m[43m)[49m

File [0;32m/opt/hostedtoolcache/Python/3.11.3/x64/lib/python3.11/site-packages/wand/image.py:9365[0m, in [0;36mImage.__init__[0;34m(self, image, blob, file, filename, pseudo, background, colorspace, depth, extract, format, height, interlace, resolution, sampling_factors, units, width)[0m
[1;32m   9363[0m     [38;5;28mself[39m[38;5;241m.[39mread(blob[38;5;241m=[39mblob)
[1;32m   9364[0m [38;5;28;01melif[39;00m filename [38;5;129;01mis[39;00m [38;5;129;01mnot[39;00m [38;5;28;01mNone[39;00m:
[0;32m-> 9365[0m     [38;5;28;43mself[39;49m[38;5;241;43m.[39;49m[43mread[49m[43m([49m[43mfilename[49m[38;5;241;43m=[39;49m[43mfilename[49m[43m)[49m
[1;32m   9366[0m [38;5;66;03m# clear the wand format, otherwise any subsequent call to[39;00m
[1;32m   9367[0m [38;5;66;03m# MagickGetImageBlob will silently change the image to this[39;00m
[1;32m   9368[0m [38;5;66;03m# format again.[39;00m
[1;32m   9369[0m library[38;5;241m.[39mMagickSetFormat([38;5;28mself[39m[38;5;241m.[39mwand, binary([38;5;124m"[39m[38;5;124m"[39m))

File [0;32m/opt/hostedtoolcache/Python/3.11.3/x64/lib/python3.11/site-packages/wand/image.py:10120[0m, in [0;36mImage.read[0;34m(self, file, filename, blob, background, colorspace, depth, extract, format, height, interlace, resolution, sampling_factors, units, width)[0m
[1;32m  10118[0m     r [38;5;241m=[39m library[38;5;241m.[39mMagickReadImage([38;5;28mself[39m[38;5;241m.[39mwand, filename)
[1;32m  10119[0m [38;5;28;01mif[39;00m [38;5;129;01mnot[39;00m r:
[0;32m> 10120[0m     [38;5;28;43mself[39;49m[38;5;241;43m.[39;49m[43mraise_exception[49m[43m([49m[43m)[49m
[1;32m  10121[0m     msg [38;5;241m=[39m ([38;5;124m'[39m[38;5;124mMagickReadImage returns false, but did not raise [39m[38;5;124m'[39m
[1;32m  10122[0m            [38;5;124m'[39m[38;5;124mImageMagick  exception. This can occur when a delegate [39m[38;5;124m'[39m
[1;32m  10123[0m            [38;5;124m'[39m[38;5;124mis missing, or returns EXIT_SUCCESS without generating a [39m[38;5;124m'[39m
[1;32m  10124[0m            [38;5;124m'[39m[38;5;124mraster.[39m[38;5;124m'[39m)
[1;32m  10125[0m     [38;5;28;01mraise[39;00m WandRuntimeError(msg)

File [0;32m/opt/hostedtoolcache/Python/3.11.3/x64/lib/python3.11/site-packages/wand/resource.py:225[0m, in [0;36mResource.raise_exception[0;34m(self, stacklevel)[0m
[1;32m    223[0m     warnings[38;5;241m.[39mwarn(e, stacklevel[38;5;241m=[39mstacklevel [38;5;241m+[39m [38;5;241m1[39m)
[1;32m    224[0m [38;5;28;01melif[39;00m [38;5;28misinstance[39m(e, [38;5;167;01mException[39;00m):
[0;32m--> 225[0m     [38;5;28;01mraise[39;00m e

[0;31mPolicyError[0m: attempt to perform an operation not allowed by the security policy `PDF' @ error/constitute.c/IsCoderAuthorized/421

